Workbook

Sheet Export Summary
B3: This document was exported from Numbers. Each table was converted to an Excel worksheet. All other objects on each Numbers sheet were placed on separate worksheets. Please be aware that formula calculations may differ in Excel.
B7: Numbers Sheet Name | C7: Numbers Table Name | D7: Excel Worksheet Name
B9: Data
C10: Table 1 | D10: Data
B11: Consumption
C12: Table 1 | D12: Consumption
B13: PDVPlot
C14: "All Drawings from the Sheet" | D14: PDVPlot
B15: ConsumptionPlot
C16: "All Drawings from the Sheet" | D16: ConsumptionPlot
B17: Calculations
C18: Table 1 | D18: Calculations

Sheet Data
A1: Shiller, R., U.S.Stock Price Data, Annual, with consumption, both short and long rates, and present value calculations.
A2: An Update of Data shown in Chapter 26 of Market Volatility, R. Shiller, MIT Press, 1989, and Irrational Exuberance, Princeton 2015. | U2: CAPE
B3: P | C3: D | D3: E | E3: R | F3: RLONG | G3: CPI | H3: RealR | I3: C | K3: RealP | L3: P* | M3: P*r | N3: P*C | O3: RealD | P3: Return | Q3: ln(1+ret) | R3: RealE | S3: P/E | T3: E10 | U3: P/E10
B4: S&P | C4: Dividends | D4: Earnings | E4: One-Year | F4: Long | G4: Consumer | H4: Real | I4: Real Per | K4: RealP | L4: Present | M4: Present | N4: Present | O4: RealD | P4: on | R4: RealE | S4: Price | T4: Ten-Year | U4: Price
B5: Composite | C5: Accruing | D5: Accruing | E5: Interest | F5: Government | G5: Price | H5: One-Year | I5: Capita | K5: Stock | L5: Value | M5: Value | N5: Value | O5: S&P | P5: S&P | R5: Earnings | S5: Earnings | T5: Average | U5: Earnings
B6: Stock | C6: to | D6: to | E6: Rate | F6: Bond | G6: Index | H6: Interest | I6: Consumption | K6: Price | L6: of Real | M6: of Real | N6: of Real | O6: Dividend | P6: Composite | S6: Ratio | T6: of | U6: Ratio
B7: Price | C7: Index | D7: Index | F7: Yield | H7: Rate | I7: (See | L7: Dividends | M7: Dividends | N7: Dividends | S7: One-Year | T7: Real | U7: Ten-Year
B8: Index | F8: 10yrpost53 | I8: Consumption | L8: Const r | M8: Market r | N8: Cons disc. | S8: Earnings | T8: Earnings | U8: Earnings
A9: 1871 | B9: 4.44 | C9: 0.26 | D9: 0.4 | E9: 6.35 | F9: 5.32 | G9: 12.464061 | H9: =(1+E9/100)*G9/G10 -> 1.0475042 | I9: Tab) | J9: =1871 -> 1871 | K9: =B9*$G$151/G9 -> 82.031306 | L9: =O9+L10/(1+'Calculations'!$E$3) -> 112.0186 | M9: =O9+M10/(H9+'Calculations'!$E$3-'Calculations'!$E$1+1) -> 63.650374 | O9: =C9*$G$151/G10 -> 4.731385 | P9: =(K10-K9+O9)/K9 -> 0.13580891 | Q9: =LN(1+P9) -> 0.1273451 | R9: =D9*$G$151/G10 -> 7.2790538
A10: 1872 | B10: 4.86 | C10: 0.3 | D10: 0.43 | E10: 7.81 | F10: 5.36 | G10: 12.654392 | H10: =(1+E10/100)*G10/G11 -> 1.0543202 | I10: in 2005 | J10: =J9+1 -> 1872 | K10: =B10*$G$151/G10 -> 88.440504 | L10: =O10+L11/(1+'Calculations'!$E$3) -> 114.29396 | M10: =O10+M11/(H10+'Calculations'!$E$3-'Calculations'!$E$1+1) -> 63.962044 | O10: =C10*$G$151/G11 -> 5.3388741 | P10: =(K11-K10+O10)/K10 -> 0.088615417 | Q10: =LN(1+P10) -> 0.08490663 | R10: =D10*$G$151/G11 -> 7.6523862 | S10: =K10/R9 -> 12.15
A11: 1873 | B11: 5.11 | C11: 0.33 | D11: 0.46 | E11: 8.35 | F11: 5.58 | G11: 12.939807 | H11: =(1+E11/100)*G11/G12 -> 1.1335111 | I11: dollars | J11: =J10+1 -> 1873 | K11: =B11*$G$151/G11 -> 90.938822 | L11: =O11+L12/(1+'Calculations'!$E$3) -> 116.07075 | M11: =O11+M12/(H11+'Calculations'!$E$3-'Calculations'!$E$1+1) -> 64.040481 | O11: =C11*$G$151/G12 -> 6.1438305 | P11: =(K12-K11+O11)/K11 -> 0.021589702 | Q11: =LN(1+P11) -> 0.021359945 | R11: =D11*$G$151/G12 -> 8.5641273 | S11: =K11/R10 -> 11.883721
A12: 1874 | B12: 4.66 | C12: 0.33 | D12: 0.46 | E12: 6.86 | F12: 5.47 | G12: 12.368896 | H12: =(1+E12/100)*G12/G13 -> 1.1480763 | J12: =J11+1 -> 1874 | K12: =B12*$G$151/G12 -> 86.758333 | L12: =O12+L13/(1+'Calculations'!$E$3) -> 117.10606 | M12: =O12+M13/(H12+'Calculations'!$E$3-'Calculations'!$E$1+1) -> 67.831712 | O12: =C12*$G$151/G13 -> 6.6007734 | P12: =(K13-K12+O12)/K12 -> 0.12279028 | Q12: =LN(1+P12) -> 0.11581691 | R12: =D12*$G$151/G13 -> 9.201078 | S12: =K12/R11 -> 10.130435
A13: 1875 | B13: 4.54 | C13: 0.3 | D13: 0.36 | E13: 4.96 | F13: 5.07 | G13: 11.512651 | H13: =(1+E13/100)*G13/G14 -> 1.1140548 | J13: =J12+1 -> 1875 | K13: =B13*$G$151/G13 -> 90.81064 | L13: =O13+L14/(1+'Calculations'!$E$3) -> 117.7222 | M13: =O13+M14/(H13+'Calculations'!$E$3-'Calculations'!$E$1+1) -> 72.630007 | O13: =C13*$G$151/G14 -> 6.3691995 | P13: =(K14-K13+O13)/K13 -> 0.11284279 | Q13: =LN(1+P13) -> 0.10691781 | R13: =D13*$G$151/G14 -> 7.6430394 | S13: =K13/R12 -> 9.8695652
A14: 1876 | B14: 4.46 | C14: 0.3 | D14: 0.28 | E14: 5.33 | F14: 4.59 | G14: 10.846575 | H14: =(1+E14/100)*G14/G15 -> 1.044139 | J14: =J13+1 -> 1876 | K14: =B14*$G$151/G14 -> 94.688766 | L14: =O14+L15/(1+'Calculations'!$E$3) -> 118.62527 | M14: =O14+M15/(H14+'Calculations'!$E$3-'Calculations'!$E$1+1) -> 76.341964 | O14: =C14*$G$151/G15 -> 6.3138038 | P14: =(K15-K14+O14)/K14 -> -0.14427917 | Q14: =LN(1+P14) -> -0.15581109 | R14: =D14*$G$151/G15 -> 5.8928836 | S14: =K14/R13 -> 12.388889
A15: 1877 | B15: 3.55 | C15: 0.19 | D15: 0.3 | E15: 5.03 | F15: 4.45 | G15: 10.94174 | H15: =(1+E15/100)*G15/G16 -> 1.2452051 | J15: =J14+1 -> 1877 | K15: =B15*$G$151/G15 -> 74.713345 | L15: =O15+L16/(1+'Calculations'!$E$3) -> 119.64633 | M15: =O15+M16/(H15+'Calculations'!$E$3-'Calculations'!$E$1+1) -> 75.786424 | O15: =C15*$G$151/G16 -> 4.7407928 | P15: =(K16-K15+O15)/K15 -> 0.14883493 | Q15: =LN(1+P15) -> 0.13874833 | R15: =D15*$G$151/G16 -> 7.4854623 | S15: =K15/R14 -> 12.678571
A16: 1878 | B16: 3.25 | C16: 0.18 | D16: 0.31 | E16: 4.9 | F16: 4.34 | G16: 9.2290893 | H16: =(1+E16/100)*G16/G17 -> 1.1695687 | J16: =J15+1 -> 1878 | K16: =B16*$G$151/G16 -> 81.092508 | L16: =O16+L17/(1+'Calculations'!$E$3) -> 122.40982 | M16: =O16+M17/(H16+'Calculations'!$E$3-'Calculations'!$E$1+1) -> 91.172431 | O16: =C16*$G$151/G17 -> 5.0074904 | P16: =(K17-K16+O16)/K16 -> 0.28989612 | Q16: =LN(1+P16) -> 0.25456169 | R16: =D16*$G$151/G17 -> 8.6240113 | S16: =K16/R15 -> 10.833333
A17: 1879 | B17: 3.58 | C17: 0.2 | D17: 0.38 | E17: 4.25 | F17: 4.22 | G17: 8.2776793 | H17: =(1+E17/100)*G17/G18 -> 0.86378329 | J17: =J16+1 -> 1879 | K17: =B17*$G$151/G17 -> 99.593421 | L17: =O17+L18/(1+'Calculations'!$E$3) -> 125.06968 | M17: =O17+M18/(H17+'Calculations'!$E$3-'Calculations'!$E$1+1) -> 104.05774 | O17: =C17*$G$151/G18 -> 4.6100576 | P17: =(K18-K17+O17)/K17 -> 0.22896703 | Q17: =LN(1+P17) -> 0.206174 | R17: =D17*$G$151/G18 -> 8.7591095 | S17: =K17/R16 -> 11.548387
A18: 1880 | B18: 5.11 | C18: 0.26 | D18: 0.49 | E18: 5.1 | F18: 4.02 | G18: 9.9903306 | H18: =(1+E18/100)*G18/G19 -> 1.1147011 | J18: =J17+1 -> 1880 | K18: =B18*$G$151/G18 -> 117.78697 | L18: =O18+L19/(1+'Calculations'!$E$3) -> 128.32663 | M18: =O18+M19/(H18+'Calculations'!$E$3-'Calculations'!$E$1+1) -> 89.689093 | O18: =C18*$G$151/G19 -> 6.3563151 | P18: =(K19-K18+O18)/K18 -> 0.3387347 | Q18: =LN(1+P18) -> 0.29172492 | R18: =D18*$G$151/G19 -> 11.979209 | S18: =K18/R17 -> 13.447368 | T18: =AVERAGE(R9:R18) -> 8.3080361
A19: 1881 | B19: 6.19 | C19: 0.32 | D19: 0.44 | E19: 4.79 | F19: 3.7 | G19: 9.4194198 | H19: =(1+E19/100)*G19/G20 -> 0.96955282 | J19: =J18+1 -> 1881 | K19: =B19*$G$151/G19 -> 151.32919 | L19: =O19+L20/(1+'Calculations'!$E$3) -> 129.93598 | M19: =O19+M20/(H19+'Calculations'!$E$3-'Calculations'!$E$1+1) -> 96.065186 | O19: =C19*$G$151/G20 -> 7.2382517 | P19: =(K20-K19+O19)/K19 -> -0.067292278 | Q19: =LN(1+P19) -> -0.069663394 | R19: =D19*$G$151/G20 -> 9.952596 | S19: =K19/R18 -> 12.632653 | T19: =AVERAGE(R10:R19) -> 8.5753903 | U19: =K19/T18 -> 18.214797
A20: 1882 | B20: 5.92 | C20: 0.32 | D20: 0.43 | E20: 5.26 | F20: 3.62 | G20: 10.18058 | H20: =(1+E20/100)*G20/G21 -> 1.072645 | J20: =J19+1 -> 1882 | K20: =B20*$G$151/G20 -> 133.90766 | L20: =O20+L21/(1+'Calculations'!$E$3) -> 130.71091 | M20: =O20+M21/(H20+'Calculations'!$E$3-'Calculations'!$E$1+1) -> 89.505718 | O20: =C20*$G$151/G21 -> 7.3760922 | P20: =(K21-K20+O20)/K20 -> 0.055191851 | Q20: =LN(1+P20) -> 0.0537226 | R20: =D20*$G$151/G21 -> 9.9116239 | S20: =K20/R19 -> 13.454545 | T20: =AVERAGE(R11:R20) -> 8.8013141 | U20: =K20/T19 -> 15.615342
A21: 1883 | B21: 5.81 | C21: 0.33 | D21: 0.4 | E21: 5.35 | F21: 3.63 | G21: 9.9903306 | H21: =(1+E21/100)*G21/G22 -> 1.1403956 | J21: =J20+1 -> 1883 | K21: =B21*$G$151/G21 -> 133.92217 | L21: =O21+L22/(1+'Calculations'!$E$3) -> 131.3896 | M21: =O21+M22/(H21+'Calculations'!$E$3-'Calculations'!$E$1+1) -> 91.224157 | O21: =C21*$G$151/G22 -> 8.2340085 | P21: =(K22-K21+O21)/K21 -> 0.026588697 | Q21: =LN(1+P21) -> 0.026241361 | R21: =D21*$G$151/G22 -> 9.9806164 | S21: =K21/R20 -> 13.511628 | T21: =AVERAGE(R12:R21) -> 8.942963 | U21: =K21/T20 -> 15.216157
A22: 1884 | B22: 5.18 | C22: 0.31 | D22: 0.31 | E22: 5.65 | F22: 3.62 | G22: 9.2290893 | H22: =(1+E22/100)*G22/G23 -> 1.1779307 | J22: =J21+1 -> 1884 | K22: =B22*$G$151/G22 -> 129.24898 | L22: =O22+L23/(1+'Calculations'!$E$3) -> 131.19867 | M22: =O22+M23/(H22+'Calculations'!$E$3-'Calculations'!$E$1+1) -> 97.802602 | O22: =C22*$G$151/G23 -> 8.6240113 | P22: =(K23-K22+O22)/K22 -> -0.020663618 | Q22: =LN(1+P22) -> -0.020880098 | R22: =D22*$G$151/G23 -> 8.6240113 | S22: =K22/R21 -> 12.95 | T22: =AVERAGE(R13:R22) -> 8.8852563 | U22: =K22/T21 -> 14.452591
A23: 1885 | B23: 4.24 | C23: 0.24 | D23: 0.27 | E23: 4.22 | F23: 3.52 | G23: 8.2776793 | H23: =(1+E23/100)*G23/G24 -> 1.0794228 | J23: =J22+1 -> 1885 | K23: =B23*$G$151/G23 -> 117.95422 | L23: =O23+L24/(1+'Calculations'!$E$3) -> 130.5798 | M23: =O23+M24/(H23+'Calculations'!$E$3-'Calculations'!$E$1+1) -> 108.44291 | O23: =C23*$G$151/G24 -> 6.9151145 | P23: =(K24-K23+O23)/K23 -> 0.32884263 | Q23: =LN(1+P23) -> 0.28430836 | R23: =D23*$G$151/G24 -> 7.7795038 | S23: =K23/R22 -> 13.677419 | T23: =AVERAGE(R14:R23) -> 8.8989027 | U23: =K23/T22 -> 13.275275
A24: 1886 | B24: 5.2 | C24: 0.22 | D24: 0.33 | E24: 4.26 | F24: 3.37 | G24: 7.9922321 | H24: =(1+E24/100)*G24/G25 -> 1.0426 | J24: =J23+1 -> 1886 | K24: =B24*$G$151/G24 -> 149.82748 | L24: =O24+L25/(1+'Calculations'!$E$3) -> 131.74101 | M24: =O24+M25/(H24+'Calculations'!$E$3-'Calculations'!$E$1+1) -> 113.45849 | O24: =C24*$G$151/G25 -> 6.3388549 | P24: =(K25-K24+O24)/K24 -> 0.11538462 | Q24: =LN(1+P24) -> 0.10919929 | R24: =D24*$G$151/G25 -> 9.5082824 | S24: =K24/R23 -> 19.259259 | T24: =AVERAGE(R15:R24) -> 9.2604426 | U24: =K24/T23 -> 16.836624
A25: 1887 | B25: 5.58 | C25: 0.25 | D25: 0.36 | E25: 6.11 | F25: 3.52 | G25: 7.9922321 | H25: =(1+E25/100)*G25/G26 -> 1.0128646 | J25: =J24+1 -> 1887 | K25: =B25*$G$151/G25 -> 160.77641 | L25: =O25+L26/(1+'Calculations'!$E$3) -> 133.59196 | M25: =O25+M26/(H25+'Calculations'!$E$3-'Calculations'!$E$1+1) -> 115.76299 | O25: =C25*$G$151/G26 -> 6.8757994 | P25: =(K26-K25+O25)/K25 -> -0.048879265 | Q25: =LN(1+P25) -> -0.050114269 | R25: =D25*$G$151/G26 -> 9.9011512 | S25: =K25/R24 -> 16.909091 | T25: =AVERAGE(R16:R25) -> 9.5020115 | U25: =K25/T24 -> 17.361634
A26: 1888 | B26: 5.31 | C26: 0.23 | D26: 0.26 | E26: 5.02 | F26: 3.67 | G26: 8.3728446 | H26: =(1+E26/100)*G26/G27 -> 1.1002135 | J26: =J25+1 -> 1888 | K26: =B26*$G$151/G26 -> 146.04198 | L26: =O26+L27/(1+'Calculations'!$E$3) -> 134.99177 | M26: =O26+M27/(H26+'Calculations'!$E$3-'Calculations'!$E$1+1) -> 114.43537 | O26: =C26*$G$151/G27 -> 6.6269847 | P26: =(K27-K26+O26)/K26 -> 0.079189592 | Q26: =LN(1+P26) -> 0.076210382 | R26: =D26*$G$151/G27 -> 7.491374 | S26: =K26/R25 -> 14.75 | T26: =AVERAGE(R17:R26) -> 9.3887478 | U26: =K26/T25 -> 15.369586
A27: 1889 | B27: 5.24 | C27: 0.22 | D27: 0.3 | E27: 4.68 | F27: 3.45 | G27: 7.9922321 | H27: =(1+E27/100)*G27/G28 -> 1.0991397 | I27: ='Consumption'!G5 -> 2731.5701 | J27: =J26+1 -> 1889 | K27: =B27*$G$151/G27 -> 150.98 | L27: =O27+L28/(1+'Calculations'!$E$3) -> 136.74807 | M27: =O27+M28/(H27+'Calculations'!$E$3-'Calculations'!$E$1+1) -> 122.71853 | N27: =(I27/I28)^4*(O27+N28) -> 108.81069 | O27: =C27*$G$151/G28 -> 6.6557957 | P27: =(K28-K27+O27)/K27 -> 0.12213707 | Q27: =LN(1+P27) -> 0.11523496 | R27: =D27*$G$151/G28 -> 9.076085 | S27: =K27/R26 -> 20.153846 | T27: =AVERAGE(R18:R27) -> 9.4204453 | U27: =K27/T26 -> 16.080952
A28: 1890 | B28: 5.38 | C28: 0.22 | D28: 0.29 | E28: 5.41 | F28: 3.42 | G28: 7.6116519 | H28: =(1+E28/100)*G28/G29 -> 1.0283904 | I28: ='Consumption'!G6 -> 2674.7398 | J28: =J27+1 -> 1890 | K28: =B28*$G$151/G28 -> 162.76446 | L28: =O28+L29/(1+'Calculations'!$E$3) -> 138.58838 | M28: =O28+M29/(H28+'Calculations'!$E$3-'Calculations'!$E$1+1) -> 131.98985 | N28: =(I28/I29)^4*(O28+N29) -> 93.378353 | O28: =C28*$G$151/G29 -> 6.4934602 | P28: =(K29-K28+O28)/K28 -> -0.082418936 | Q28: =LN(1+P28) -> -0.08601435 | R28: =D28*$G$151/G29 -> 8.5595612 | S28: =K28/R27 -> 17.933333 | T28: =AVERAGE(R19:R28) -> 9.0784805 | U28: =K28/T27 -> 17.277788
A29: 1891 | B29: 4.84 | C29: 0.22 | D29: 0.34 | E29: 5.97 | F29: 3.62 | G29: 7.801942 | H29: =(1+E29/100)*G29/G30 -> 1.1285119 | I29: ='Consumption'!G7 -> 2802.8275 | J29: =J28+1 -> 1891 | K29: =B29*$G$151/G29 -> 142.85612 | L29: =O29+L30/(1+'Calculations'!$E$3) -> 140.72181 | M29: =O29+M30/(H29+'Calculations'!$E$3-'Calculations'!$E$1+1) -> 133.83929 | N29: =(I29/I30)^4*(O29+N30) -> 106.09802 | O29: =C29*$G$151/G30 -> 6.9151145 | P29: =(K30-K29+O29)/K29 -> 0.2607601 | Q29: =LN(1+P29) -> 0.23171479 | R29: =D29*$G$151/G30 -> 10.686995 | S29: =K29/R28 -> 16.689655 | T29: =AVERAGE(R20:R29) -> 9.1519205 | U29: =K29/T28 -> 15.735687
A30: 1892 | B30: 5.51 | C30: 0.24 | D30: 0.37 | E30: 3.93 | F30: 3.6 | G30: 7.3262127 | H30: =(1+E30/100)*G30/G31 -> 0.96416931 | I30: ='Consumption'!G8 -> 2877.0105 | J30: =J29+1 -> 1892 | K30: =B30*$G$151/G30 -> 173.19219 | L30: =O30+L31/(1+'Calculations'!$E$3) -> 142.54538 | M30: =O30+M31/(H30+'Calculations'!$E$3-'Calculations'!$E$1+1) -> 148.06983 | N30: =(I30/I31)^4*(O30+N31) -> 110.86923 | O30: =C30*$G$151/G31 -> 6.998425 | P30: =(K31-K30+O30)/K30 -> -0.015044426 | Q30: =LN(1+P30) -> -0.015158741 | R30: =D30*$G$151/G31 -> 10.789239 | S30: =K30/R29 -> 16.205882 | T30: =AVERAGE(R21:R30) -> 9.2396819 | U30: =K30/T29 -> 18.924136
A31: 1893 | B31: 5.61 | C31: 0.25 | D31: 0.26 | E31: 8.52 | F31: 3.75 | G31: 7.8970911 | H31: =(1+E31/100)*G31/G32 -> 1.2509954 | I31: ='Consumption'!G9 -> 2834.8462 | J31: =J30+1 -> 1893 | K31: =B31*$G$151/G31 -> 163.58819 | L31: =O31+L32/(1+'Calculations'!$E$3) -> 144.39929 | M31: =O31+M32/(H31+'Calculations'!$E$3-'Calculations'!$E$1+1) -> 141.38997 | N31: =(I31/I32)^4*(O31+N32) -> 97.512874 | O31: =C31*$G$151/G32 -> 8.4037864 | P31: =(K32-K31+O31)/K31 -> -0.060927198 | Q31: =LN(1+P31) -> -0.062862272 | R31: =D31*$G$151/G32 -> 8.7399378 | S31: =K31/R30 -> 15.162162 | T31: =AVERAGE(R22:R31) -> 9.1156141 | U31: =K31/T30 -> 17.704959
A32: 1894 | B32: 4.32 | C32: 0.21 | D32: 0.16 | E32: 3.32 | F32: 3.7 | G32: 6.8504835 | H32: =(1+E32/100)*G32/G33 -> 1.0781208 | I32: ='Consumption'!G10 -> 2698.7075 | J32: =J31+1 -> 1894 | K32: =B32*$G$151/G32 -> 145.21743 | L32: =O32+L33/(1+'Calculations'!$E$3) -> 144.87714 | M32: =O32+M33/(H32+'Calculations'!$E$3-'Calculations'!$E$1+1) -> 171.43039 | N32: =(I32/I33)^4*(O32+N33) -> 71.684178 | O32: =C32*$G$151/G33 -> 7.3660951 | P32: =(K33-K32+O32)/K32 -> 0.077293749 | Q32: =LN(1+P32) -> 0.074452108 | R32: =D32*$G$151/G33 -> 5.6122629 | S32: =K32/R31 -> 16.615385 | T32: =AVERAGE(R23:R32) -> 8.8144392 | U32: =K32/T31 -> 15.930625
A33: 1895 | B33: 4.25 | C33: 0.19 | D33: 0.25 | E33: 3.09 | F33: 3.46 | G33: 6.5650524 | H33: =(1+E33/100)*G33/G34 -> 1.0161736 | I33: ='Consumption'!G11 -> 2979.4573 | J33: =J32+1 -> 1895 | K33: =B33*$G$151/G33 -> 149.07573 | L33: =O33+L34/(1+'Calculations'!$E$3) -> 146.49165 | M33: =O33+M34/(H33+'Calculations'!$E$3-'Calculations'!$E$1+1) -> 183.13014 | N33: =(I33/I34)^4*(O33+N34) -> 99.133685 | O33: =C33*$G$151/G34 -> 6.5693588 | P33: =(K34-K33+O33)/K33 -> 0.034420896 | Q33: =LN(1+P33) -> 0.033841749 | R33: =D33*$G$151/G34 -> 8.6438931 | S33: =K33/R32 -> 26.5625 | T33: =AVERAGE(R24:R33) -> 8.9008782 | U33: =K33/T32 -> 16.912674
A34: 1896 | B34: 4.27 | C34: 0.18 | D34: 0.21 | E34: 5.76 | F34: 3.6 | G34: 6.6601934 | H34: =(1+E34/100)*G34/G35 -> 1.0887057 | I34: ='Consumption'!G12 -> 2916.2753 | J34: =J33+1 -> 1896 | K34: =B34*$G$151/G34 -> 147.63769 | L34: =O34+L35/(1+'Calculations'!$E$3) -> 149.06037 | M34: =O34+M35/(H34+'Calculations'!$E$3-'Calculations'!$E$1+1) -> 186.14139 | N34: =(I34/I35)^4*(O34+N35) -> 84.419168 | O34: =C34*$G$151/G35 -> 6.4066491 | P34: =(K35-K34+O34)/K34 -> 0.060751983 | Q34: =LN(1+P34) -> 0.058978074 | R34: =D34*$G$151/G35 -> 7.4744239 | S34: =K34/R33 -> 17.08 | T34: =AVERAGE(R25:R34) -> 8.6974923 | U34: =K34/T33 -> 16.586868
A35: 1897 | B35: 4.22 | C35: 0.18 | D35: 0.31 | E35: 3.44 | F35: 3.4 | G35: 6.4699033 | H35: =(1+E35/100)*G35/G36 -> 1.0048459 | I35: ='Consumption'!G13 -> 3089.2463 | J35: =J34+1 -> 1897 | K35: =B35*$G$151/G35 -> 150.20033 | L35: =O35+L36/(1+'Calculations'!$E$3) -> 151.97019 | M35: =O35+M36/(H35+'Calculations'!$E$3-'Calculations'!$E$1+1) -> 202.52413 | N35: =(I35/I36)^4*(O35+N36) -> 99.894303 | O35: =C35*$G$151/G36 -> 6.2236031 | P35: =(K36-K35+O35)/K35 -> 0.16479371 | Q35: =LN(1+P35) -> 0.15254399 | R35: =D35*$G$151/G36 -> 10.718427 | S35: =K35/R34 -> 20.095238 | T35: =AVERAGE(R26:R35) -> 8.7792199 | U35: =K35/T34 -> 17.269383
A36: 1898 | B36: 4.88 | C36: 0.2 | D36: 0.35 | E36: 3.55 | F36: 3.35 | G36: 6.6601934 | H36: =(1+E36/100)*G36/G37 -> 1.020915 | I36: ='Consumption'!G14 -> 3085.2755 | J36: =J35+1 -> 1898 | K36: =B36*$G$151/G36 -> 168.72879 | L36: =O36+L37/(1+'Calculations'!$E$3) -> 155.26505 | M36: =O36+M37/(H36+'Calculations'!$E$3-'Calculations'!$E$1+1) -> 204.72863 | N36: =(I36/I37)^4*(O36+N37) -> 93.158082 | O36: =C36*$G$151/G37 -> 6.817715 | P36: =(K37-K36+O36)/K36 -> 0.26875945 | Q36: =LN(1+P36) -> 0.23803961 | R36: =D36*$G$151/G37 -> 11.931001 | S36: =K36/R35 -> 15.741935 | T36: =AVERAGE(R27:R36) -> 9.2231827 | U36: =K36/T35 -> 19.21911
A37: 1899 | B37: 6.08 | C37: 0.21 | D37: 0.48 | E37: 3.36 | F37: 3.1 | G37: 6.7553425 | H37: =(1+E37/100)*G37/G38 -> 0.88416379 | I37: ='Consumption'!G15 -> 3389.8131 | J37: =J36+1 -> 1899 | K37: =B37*$G$151/G37 -> 207.25854 | L37: =O37+L38/(1+'Calculations'!$E$3) -> 158.14217 | M37: =O37+M38/(H37+'Calculations'!$E$3-'Calculations'!$E$1+1) -> 209.58841 | N37: =(I37/I38)^4*(O37+N38) -> 128.93476 | O37: =C37*$G$151/G38 -> 6.1236219 | P37: =(K38-K37+O37)/K37 -> -0.11221868 | Q37: =LN(1+P37) -> -0.11902982 | R37: =D37*$G$151/G38 -> 13.99685 | S37: =K37/R36 -> 17.371429 | T37: =AVERAGE(R28:R37) -> 9.7152592 | U37: =K37/T36 -> 22.471477
A38: 1900 | B38: 6.1 | C38: 0.3 | D38: 0.48 | E38: 4.64 | F38: 3.15 | G38: 7.8970911 | H38: =(1+E38/100)*G38/G39 -> 1.072238 | I38: ='Consumption'!G16 -> 3362.0541 | J38: =J37+1 -> 1900 | K38: =B38*$G$151/G38 -> 177.87664 | L38: =O38+L39/(1+'Calculations'!$E$3) -> 161.94662 | M38: =O38+M39/(H38+'Calculations'!$E$3-'Calculations'!$E$1+1) -> 187.64594 | N38: =(I38/I39)^4*(O38+N39) -> 118.63938 | O38: =C38*$G$151/G39 -> 8.96404 | P38: =(K39-K38+O38)/K38 -> 0.23802984 | Q38: =LN(1+P38) -> 0.21352128 | R38: =D38*$G$151/G39 -> 14.342464 | S38: =K38/R37 -> 12.708333 | T38: =AVERAGE(R29:R38) -> 10.293549 | U38: =K38/T37 -> 18.308995
... A143: 2005 | B143: 1181.41 | C143: 22.22 | D143: 69.93 | E143: 3.41 | F143: 4.22 | G143: 190.7 | H143: =(1+E143/100)*G143/G144 -> 0.99446732 | I143: ='Consumption'!G121 -> 29790.296 | J143: =J142+1 -> 2005 | K143: =B143*$G$151/G143 -> 1426.613 | L143: =O143+L144/(1+'Calculations'!$E$3) -> 748.90716 | M143: =O143+M144/(H143+'Calculations'!$E$3-'Calculations'!$E$1+1) -> 775.80149 | N143: =(I143/I144)^4*(O143+N144) -> 920.3223 | O143: =C143*$G$151/G144 -> 25.803437 | P143: =(K144-K143+O143)/K143 -> 0.058980448 | Q143: =LN(1+P143) -> 0.057306604 | R143: =D143*$G$151/G144 -> 81.207667 | S143: =K143/R142 -> 20.177797 | T143: =AVERAGE(R134:R143) -> 57.656749 | U143: =K143/T142 -> 26.127989
A144: 2006 | B144: 1278.73 | C144: 24.88 | D144: 81.51 | E144: 5.32 | F144: 4.42 | G144: 198.3 | H144: =(1+E144/100)*G144/G145 -> 1.0317839 | I144: ='Consumption'!G122 -> 30364.433 | J144: 2006 | K144: =B144*$G$151/G144 -> 1484.9518 | L144: =O144+L145/(1+'Calculations'!$E$3) -> 770.32838 | M144: =O144+M145/(H144+'Calculations'!$E$3-'Calculations'!$E$1+1) -> 774.4151 | N144: =(I144/I145)^4*(O144+N145) -> 967.54454 | O144: =C144*$G$151/G145 -> 28.304909 | P144: =(K145-K144+O144)/K144 -> 0.1101442 | Q144: =LN(1+P144) -> 0.10448992 | R144: =D144*$G$151/G145 -> 92.73043 | S144: =K144/R143 -> 18.285857 | T144: =AVERAGE(R135:R144) -> 61.324045 | U144: =K144/T143 -> 25.755039
...

Sheet Consumption
A1: This page shows how consumption data in column I of Data were constructed
B2: NIPA Table 2.3.6 | C2: NIPA Table 2.4.3 | D2: NBER Kendrick | E2: Real Consumption | F2: Population | G2: Per Capita Real Consumption
B3: Personal Consumption Expenditures | C3: Real Personal Consumption Index | D3: Personal Consumption Expenditures | E3: Inferred from Columns B,C,D | F3: From NIPA Table 7.1 Line 18
B4: Billions of Chained 2005 Dollars | C4: 2000=100 | D4: Millions of 1929 Dollars | E4: Billions of 2005 Dollars | F4: Millions | G4: In 2005 Dollars
A5: 1889 | D5: 18004 | E5: =($E$45/$D$45)*D5 -> 168.74275 | F5: 61.775 | G5: =1000*E5/F5 -> 2731.5701
A6: =A5+1 -> 1890 | D6: 17995 | E6: =($E$45/$D$45)*D6 -> 168.65839 | F6: 63.056 | G6: =1000*E6/F6 -> 2674.7398
A7: =A6+1 -> 1891 | D7: 19247 | E7: =($E$45/$D$45)*D7 -> 180.39278 | F7: 64.361 | G7: =1000*E7/F7 -> 2802.8275
A8: =A7+1 -> 1892 | D8: 20157 | E8: =($E$45/$D$45)*D8 -> 188.92177 | F8: 65.666 | G8: =1000*E8/F8 -> 2877.0105
A9: =A8+1 -> 1893 | D9: 20256 | E9: =($E$45/$D$45)*D9 -> 189.84965 | F9: 66.97 | G9: =1000*E9/F9 -> 2834.8462
A10: =A9+1 -> 1894 | D10: 19659 | E10: =($E$45/$D$45)*D10 -> 184.25426 | F10: 68.275 | G10: =1000*E10/F10 -> 2698.7075
A11: =A10+1 -> 1895 | D11: 22119 | E11: =($E$45/$D$45)*D11 -> 207.31064 | F11: 69.58 | G11: =1000*E11/F11 -> 2979.4573
A12: =A11+1 -> 1896 | D12: 22056 | E12: =($E$45/$D$45)*D12 -> 206.72017 | F12: 70.885 | G12: =1000*E12/F12 -> 2916.2753
A13: =A12+1 -> 1897 | D13: 23794 | E13: =($E$45/$D$45)*D13 -> 223.0096 | F13: 72.189 | G13: =1000*E13/F13 -> 3089.2463
A14: =A13+1 -> 1898 | D14: 24193 | E14: =($E$45/$D$45)*D14 -> 226.74924 | F14: 73.494 | G14: =1000*E14/F14 -> 3085.2755
A15: =A14+1 -> 1899 | D15: 27053 | E15: =($E$45/$D$45)*D15 -> 253.55463 | F15: 74.799 | G15: =1000*E15/F15 -> 3389.8131
A16: =A15+1 -> 1900 | D16: 27296 | E16: =($E$45/$D$45)*D16 -> 255.83215 | F16: 76.094 | G16: =1000*E16/F16 -> 3362.0541
A17: =A16+1 -> 1901 | D17: 30651 | E17: =($E$45/$D$45)*D17 -> 287.27693 | F17: 77.584 | G17: =1000*E17/F17 -> 3702.7858
... A44: =A43+1 -> 1928 | D44: 74813 | E44: =($E$45/$D$45)*D44 -> 701.1859 | F44: 120.509 | G44: =1000*E44/F44 -> 5818.5356
A45: 1929 | C45: 9.814 | D45: 78952 | E45: =($B$111/$C$111)*C45 -> 739.97874 | F45: 121.878 | G45: =1000*E45/F45 -> 6071.471
A46: =A45+1 -> 1930 | C46: 9.29 | E46: =($B$111/$C$111)*C46 -> 700.46897 | F46: 123.188 | G46: =1000*E46/F46 -> 5686.1786
A47: =A46+1 -> 1931 | C47: 9.005 | E47: =($B$111/$C$111)*C47 -> 678.97988 | F47: 124.149 | G47: =1000*E47/F47 -> 5469.0725
A48: =A47+1 -> 1932 | C48: 8.206 | E48: =($B$111/$C$111)*C48 -> 618.73503 | F48: 124.949 | G48: =1000*E48/F48 -> 4951.9006
A49: =A48+1 -> 1933 | C49: 8.028 | E49: =($B$111/$C$111)*C49 -> 605.31377 | F49: 125.69 | G49: =1000*E49/F49 -> 4815.9262
A50: =A49+1 -> 1934 | C50: 8.595 | E50: =($B$111/$C$111)*C50 -> 648.06575 | F50: 126.485 | G50: =1000*E50/F50 -> 5123.657
A51: =A50+1 -> 1935 | C51: 9.123 | E51: =($B$111/$C$111)*C51 -> 687.87712 | F51: 127.362 | G51: =1000*E51/F51 -> 5400.9604
A52: =A51+1 -> 1936 | C52: 10.046 | E52: =($B$111/$C$111)*C52 -> 757.47161 | F52: 128.181 | G52: =1000*E52/F52 -> 5909.3907
A53: =A52+1 -> 1937 | C53: 10.417 | E53: =($B$111/$C$111)*C53 -> 785.44513 | F53: 128.961 | G53: =1000*E53/F53 -> 6090.5633
A54: =A53+1 -> 1938 | C54: 10.249 | E54: =($B$111/$C$111)*C54 -> 772.77788 | F54: 129.969 | G54: =1000*E54/F54 -> 5945.8631
A55: =A54+1 -> 1939 | C55: 10.819 | E55: =($B$111/$C$111)*C55 -> 815.75606 | F55: 131.028 | G55: =1000*E55/F55 -> 6225.8148
A56: =A55+1 -> 1940 | C56: 11.382 | E56: =($B$111/$C$111)*C56 -> 858.20644 | F56: 132.122 | G56: =1000*E56/F56 -> 6495.5605
A57: =A56+1 -> 1941 | C57: 12.195 | E57: =($B$111/$C$111)*C57 -> 919.5069 | F57: 133.402 | G57: =1000*E57/F57 -> 6892.752
... A101: =A100+1 -> 1985 | C101: 60.303 | E101: =($B$111/$C$111)*C101 -> 4546.8655 | F101: 238.506 | G101: =1000*E101/F101 -> 19063.946
A102: =A101+1 -> 1986 | C102: 62.749 | E102: =($B$111/$C$111)*C102 -> 4731.2947 | F102: 240.683 | G102: =1000*E102/F102 -> 19657.785 | I102: 6079 | J102: 6291.2 | K102: 6523.4 | L102: 6865.5 | M102: 7240.9 | N102: 7608.1 | O102: 7813.9 | P102: 8021.9 | Q102: 8247.6 | R102: 8532.7 | S102: 8819 | T102: 9073.5 | U102: 9313.9 | V102: 9290.9
A103: =A102+1 -> 1987 | C103: 64.84 | E103: =($B$111/$C$111)*C103 -> 4888.9567 | F103: 242.843 | G103: =1000*E103/F103 -> 20132.171
A104: =A103+1 -> 1988 | C104: 67.468 | E104: =($B$111/$C$111)*C104 -> 5087.1088 | F104: 245.061 | G104: =1000*E104/F104 -> 20758.541
A105: =A104+1 -> 1989 | C105: 69.369 | E105: =($B$111/$C$111)*C105 -> 5230.4448 | F105: 247.387 | G105: =1000*E105/F105 -> 21142.763
A106: 1990 | C106: 70.782 | E106: =($B$111/$C$111)*C106 -> 5336.9855 | F106: 250.181 | G106: =1000*E106/F106 -> 21332.497
A107: 1991 | C107: 70.903 | E107: =($B$111/$C$111)*C107 -> 5346.1089 | F107: 253.53 | G107: =1000*E107/F107 -> 21086.691
A108: 1992 | C108: 73.224 | E108: =($B$111/$C$111)*C108 -> 5521.113 | F108: 256.922 | G108: =1000*E108/F108 -> 21489.452
A109: 1993 | C109: 75.672 | E109: =($B$111/$C$111)*C109 -> 5705.693 | F109: 260.282 | G109: =1000*E109/F109 -> 21921.197
...

Sheet PDVPlot

Sheet ConsumptionPlot

Sheet Calculations
A1: Average Real Interest Rate: | E1: =AVERAGE('Data'!H9:H151) -> 1.0272194
A2: Geometric Average Stock Return: | E2: =AVERAGE('Data'!Q9:Q151) -> 0.063264218
A3: exp(geo. Avg. return) | E3: =EXP(E2)-1 -> 0.065308276
A4: Geometric Average Dividend Growth | E4: =EXP(LN('Data'!O150/'Data'!O9)/141)-1 -> 0.013478692
